<mujoco model="h1">
  <compiler angle="radian" meshdir="meshes"/>
  <size njmax="500" nconmax="100" />
    <option gravity='0 0 -9.81' iterations='50' solver='PGS' timestep='0.001'/>

  <default>
    <default class="h1">
      <geom type="mesh"/>
      <joint damping="1" armature="0.1"/>
      <default class="visual">
        <geom contype="0" conaffinity="0" group="2" material="black"/>
      </default>
      <default class="collision">
        <geom group="3" mass="0" density="0"/>
      </default>
      <site size="0.001" rgba="0.5 0.5 0.5 0.3" group="4"/>
    </default>
  </default>

  <asset>
    <material name="black" rgba="0.1 0.1 0.1 1"/>
    <material name="white" rgba="1 1 1 1"/>
    <mesh file="pelvis.STL"/>
    <mesh file="left_hip_yaw_link.STL"/>
    <mesh file="left_hip_roll_link.STL"/>
    <mesh file="left_hip_pitch_link.STL"/>
    <mesh file="left_knee_link.STL"/>
    <mesh file="left_ankle_link.STL"/>
    <mesh file="right_hip_yaw_link.STL"/>
    <mesh file="right_hip_roll_link.STL"/>
    <mesh file="right_hip_pitch_link.STL"/>
    <mesh file="right_knee_link.STL"/>
    <mesh file="right_ankle_link.STL"/>
    <mesh file="torso_link.STL"/>
    <mesh file="left_shoulder_pitch_link.STL"/>
    <mesh file="left_shoulder_roll_link.STL"/>
    <mesh file="left_shoulder_yaw_link.STL"/>
    <mesh file="left_elbow_link.STL"/>
    <mesh file="right_shoulder_pitch_link.STL"/>
    <mesh file="right_shoulder_roll_link.STL"/>
    <mesh file="right_shoulder_yaw_link.STL"/>
    <mesh file="right_elbow_link.STL"/>
    <mesh file="logo_link.STL"/>
  </asset>

  <worldbody>
    <body name="pelvis" pos="0 0 1.5" childclass="h1">
      <inertial pos="-0.0002 4e-05 -0.04522"  mass="5.39" fullinertia='0.044582 0.0082464 0.049021 8.7034E-05 -1.9893E-05 4.021E-06' />
      <freejoint/>
      <site name="imu" size="0.01" pos="-0.04452 -0.01891 0.27756"/>
      <geom class="visual" mesh="pelvis"/>
      <geom class="collision" mesh="pelvis"/>
      <body name="left_hip_yaw_link" pos="0 0.0875 -0.1742">
        <inertial pos="-0.04923 0.0001 0.0072"  mass="2.244" fullinertia='0.0025731 0.0030444 0.0022883 9.159E-06 -0.00051948 1.949E-06' />
        <joint name="left_hip_yaw_joint" axis="0 0 1" range="-0.43 0.43"/>
        <geom class="visual" mesh="left_hip_yaw_link"/>
        <geom size="0.06 0.035" pos="-0.067 0 0" quat="0.707123 0 0.70709 0" type="cylinder" class="collision"/>
        <body name="left_hip_roll_link" pos="0.039468 0 0">
          <inertial pos="-0.0058 -0.00319 -9e-05" mass="2.232" fullinertia='0.0020603 0.0022482 0.0024323 3.2115E-05 2.878E-06 -7.813E-06'/>
          <joint name="left_hip_roll_joint" axis="1 0 0" range="-0.43 0.43"/>
          <geom class="visual" mesh="left_hip_roll_link"/>
          <geom class="collision" mesh="left_hip_roll_link"/>
          <body name="left_hip_pitch_link" pos="0 0.11536 0">
            <inertial pos="0.00746 -0.02346 -0.08193" mass="4.152"
              fullinertia='0.082618 0.081579 0.0060081 -0.00066654 0.0040725 0.0072024'/>
            <joint name="left_hip_pitch_joint" axis="0 1 0" range="-1.57 1.57"/>
            <geom class="visual" mesh="left_hip_pitch_link"/>
            <geom class="collision" mesh="left_hip_pitch_link"/>
            <body name="left_knee_link" pos="0 0 -0.4">
              <inertial pos="-0.00136 -0.00512 -0.1384" mass="1.721"
                fullinertia='0.012205 0.012509 0.0020629 -6.8431E-05 0.0010862 0.00022549'/>
              <joint name="left_knee_joint" axis="0 1 0" range="-0.26 2.05"/>
              <geom class="visual" mesh="left_knee_link"/>
              <geom class="collision" mesh="left_knee_link"/>
              <body name="left_ankle_link" pos="0 0 -0.4">
                <inertial pos="0.048568 0 -0.045609" mass="0.552448"
                  fullinertia='0.000159668 0.002900286 0.002805438 -0.000000005 0.000141063 0.000000014'/>
                <joint name="left_ankle_joint" axis="0 1 0" range="-0.87 0.52"/>
                <geom class="visual" mesh="left_ankle_link"/>
                <geom class="collision" mesh="left_ankle_link"/>
              </body>
            </body>
          </body>
        </body>
      </body>
      <body name="right_hip_yaw_link" pos="0 -0.0875 -0.1742">
        <inertial pos="-0.04923 -0.0001 0.0072" mass="2.244"
          fullinertia='0.0025731 0.0030444 0.0022883 -9.159E-06 -0.00051948 -1.949E-06'/>
        <joint name="right_hip_yaw_joint" axis="0 0 1" range="-0.43 0.43"/>
        <geom class="visual" mesh="right_hip_yaw_link"/>
        <geom size="0.06 0.035" pos="-0.067 0 0" quat="0.707123 0 0.70709 0" type="cylinder" class="collision"/>
        <body name="right_hip_roll_link" pos="0.039468 0 0">
          <inertial pos="-0.0058 0.00319 -9e-05" mass="2.232"
            fullinertia='0.0020603 0.0022482 0.0024323 -3.2115E-05 2.878E-06 7.813E-06'/>
          <joint name="right_hip_roll_joint" axis="1 0 0" range="-0.43 0.43"/>
          <geom class="visual" mesh="right_hip_roll_link"/>
          <geom class="collision" mesh="right_hip_roll_link"/>
          <body name="right_hip_pitch_link" pos="0 -0.11536 0">
            <inertial pos="0.00746 0.02346 -0.08193" mass="4.152"
              fullinertia='0.082618 0.081579 0.0060081 0.00066654 0.0040725 -0.0072024'/>
            <joint name="right_hip_pitch_joint" axis="0 1 0" range="-1.57 1.57"/>
            <geom class="visual" mesh="right_hip_pitch_link"/>
            <geom class="collision" mesh="right_hip_pitch_link"/>
            <body name="right_knee_link" pos="0 0 -0.4">
              <inertial pos="-0.00136 0.00512 -0.1384" mass="1.721"
                fullinertia='0.012205 0.012509 0.0020629 6.8431E-05 0.0010862 -0.00022549'/>
              <joint name="right_knee_joint" axis="0 1 0" range="-0.26 2.05"/>
              <geom class="visual" mesh="right_knee_link"/>
              <geom class="collision" mesh="right_knee_link"/>
              <body name="right_ankle_link" pos="0 0 -0.4">
                <inertial pos="0.048568 0 -0.045609" mass="0.552448"
                  fullinertia='0.000159668 0.002900286 0.002805438 0.000000005 0.000141063 -0.000000014'/>
                <joint name="right_ankle_joint" axis="0 1 0" range="-0.87 0.52"/>
                <geom class="visual" mesh="right_ankle_link"/>
                <geom class="collision" mesh="right_ankle_link"/>
              </body>
            </body>
          </body>
        </body>
      </body>
      <body name="torso_link">
        <inertial pos="0.000489 0.002797 0.20484" mass="17.789"
          fullinertia='0.4873 0.40963 0.12785 -0.00053763 0.0020276 -0.00074582'/>
        <joint name="torso_joint" axis="0 0 1" range="-2.35 2.35"/>
        <geom class="visual" mesh="torso_link"/>
        <!-- <geom class="collision" mesh="torso_link"/> -->
        <geom class="visual" material="white" mesh="logo_link"/>
        <!-- <site name="imu" size="0.01" pos="-0.04452 -0.01891 0.27756"/> -->
        <body name="left_shoulder_pitch_link" pos="0.0055 0.15535 0.42999" quat="0.976296 0.216438 0 0">
          <inertial pos="0.005045 0.053657 -0.015715" mass="1.033"
            fullinertia='0.0012985 0.00087279 0.00097338 -1.7333E-05 8.683E-06 3.9656E-05'/>
          <joint name="left_shoulder_pitch_joint" axis="0 1 0" range="-2.87 2.87"/>
          <geom class="visual" mesh="left_shoulder_pitch_link"/>
          <geom class="collision" mesh="left_shoulder_pitch_link"/>
          <body name="left_shoulder_roll_link" pos="-0.0055 0.0565 -0.0165" quat="0.976296 -0.216438 0 0">
            <inertial pos="0.000679 0.00115 -0.094076" mass="0.793"
              fullinertia='0.0015742 0.0016973 0.0010183 2.298E-06 -7.2265E-05 -6.3691E-05'/>
            <joint name="left_shoulder_roll_joint" axis="1 0 0" range="-0.34 3.11"/>
            <geom class="visual" mesh="left_shoulder_roll_link"/>
            <geom class="collision" mesh="left_shoulder_roll_link"/>
            <body name="left_shoulder_yaw_link" pos="0 0 -0.1343">
              <inertial pos="0.01365 0.002767 -0.16266" mass="0.839"
                fullinertia='0.003664 0.0040789 0.00066383 -1.0671E-05 0.00034733 7.0213E-05'/>
              <joint name="left_shoulder_yaw_joint" axis="0 0 1" range="-1.3 4.45"/>
              <geom class="visual" mesh="left_shoulder_yaw_link"/>
              <geom class="collision" mesh="left_shoulder_yaw_link"/>
              <body name="left_elbow_link" pos="0.0185 0 -0.198">
                <inertial pos="0.15908 -0.000144 -0.015776" mass="0.669"
                  fullinertia='0.00042388 0.0060062 0.0060023 -3.6086E-05 0.00029293 4.664E-06'/>
                <joint name="left_elbow_joint" axis="0 1 0" range="-1.25 2.61"/>
                <geom class="visual" mesh="left_elbow_link"/>
                <geom class="collision" mesh="left_elbow_link"/>
              </body>
            </body>
          </body>
        </body>
        <body name="right_shoulder_pitch_link" pos="0.0055 -0.15535 0.42999" quat="0.976296 -0.216438 0 0">
          <inertial pos="0.005045 -0.053657 -0.015715" mass="1.033"
            fullinertia='0.0012985 0.00087279 0.00097338 1.7333E-05 8.683E-06 -3.9656E-05'/>
          <joint name="right_shoulder_pitch_joint" axis="0 1 0" range="-2.87 2.87"/>
          <geom class="visual" mesh="right_shoulder_pitch_link"/>
          <geom class="collision" mesh="right_shoulder_pitch_link"/>
          <body name="right_shoulder_roll_link" pos="-0.0055 -0.0565 -0.0165" quat="0.976296 0.216438 0 0">
            <inertial pos="0.000679 -0.00115 -0.094076" mass="0.793"
              fullinertia='0.0015742 0.0016973 0.0010183 -2.298E-06 -7.2265E-05 6.3691E-05'/>
            <joint name="right_shoulder_roll_joint" axis="1 0 0" range="-3.11 0.34"/>
            <geom class="visual" mesh="right_shoulder_roll_link"/>
            <geom class="collision" mesh="right_shoulder_roll_link"/>
            <body name="right_shoulder_yaw_link" pos="0 0 -0.1343">
              <inertial pos="0.01365 -0.002767 -0.16266" mass="0.839"
                fullinertia='0.003664 0.0040789 0.00066383 1.0671E-05 0.00034733 -7.0213E-05'/>
              <joint name="right_shoulder_yaw_joint" axis="0 0 1" range="-4.45 1.3"/>
              <geom class="visual" mesh="right_shoulder_yaw_link"/>
              <geom class="collision" mesh="right_shoulder_yaw_link"/>
              <body name="right_elbow_link" pos="0.0185 0 -0.198">
                <inertial pos="0.15908 0.000144 -0.015776" mass="0.669"
                  fullinertia='0.00042388 0.0060062 0.0060023 3.6086E-05 0.00029293 -4.664E-06'/>
                <joint name="right_elbow_joint" axis="0 1 0" range="-1.25 2.61"/>
                <geom class="visual" mesh="right_elbow_link"/>
                <geom class="collision" mesh="right_elbow_link"/>
              </body>
            </body>
          </body>
        </body>
      </body>
    </body>
  </worldbody>

  <actuator>
    <motor class="h1" name="left_hip_yaw_joint" joint="left_hip_yaw_joint" ctrlrange="-1000 1000"/>
    <motor class="h1" name="left_hip_roll_joint" joint="left_hip_roll_joint" ctrlrange="-1000 1000"/>
    <motor class="h1" name="left_hip_pitch_joint" joint="left_hip_pitch_joint" ctrlrange="-1000 1000"/>
    <motor class="h1" name="left_knee_joint" joint="left_knee_joint" ctrlrange="-1000 1000"/>
    <motor class="h1" name="left_ankle_joint" joint="left_ankle_joint" ctrlrange="-1000 1000"/>
    <motor class="h1" name="right_hip_yaw_joint" joint="right_hip_yaw_joint" ctrlrange="-1000 1000"/>
    <motor class="h1" name="right_hip_roll_joint" joint="right_hip_roll_joint" ctrlrange="-1000 1000"/>
    <motor class="h1" name="right_hip_pitch_joint" joint="right_hip_pitch_joint" ctrlrange="-1000 1000"/>
    <motor class="h1" name="right_knee_joint" joint="right_knee_joint" ctrlrange="-1000 1000"/>
    <motor class="h1" name="right_ankle_joint" joint="right_ankle_joint" ctrlrange="-1000 1000"/>
    <motor class="h1" name="torso_joint" joint="torso_joint" ctrlrange="-20000 20000"/>
    <motor class="h1" name="left_shoulder_pitch_joint" joint="left_shoulder_pitch_joint" ctrlrange="-40 40"/>
    <motor class="h1" name="left_shoulder_roll_joint" joint="left_shoulder_roll_joint" ctrlrange="-40 40"/>
    <motor class="h1" name="left_shoulder_yaw_joint" joint="left_shoulder_yaw_joint" ctrlrange="-18 18"/>
    <motor class="h1" name="left_elbow_joint" joint="left_elbow_joint" ctrlrange="-18 18"/>
    <motor class="h1" name="right_shoulder_pitch_joint" joint="right_shoulder_pitch_joint" ctrlrange="-40 40"/>
    <motor class="h1" name="right_shoulder_roll_joint" joint="right_shoulder_roll_joint" ctrlrange="-40 40"/>
    <motor class="h1" name="right_shoulder_yaw_joint" joint="right_shoulder_yaw_joint" ctrlrange="-18 18"/>
    <motor class="h1" name="right_elbow_joint" joint="right_elbow_joint" ctrlrange="-18 18"/>
  </actuator>

  <sensor>
    <jointpos name="left_hip_yaw_pos"     joint="left_hip_yaw_joint"/>
    <jointpos name="left_hip_roll_pos"   joint="left_hip_roll_joint"/>
    <jointpos name="left_hip_pitch_pos"    joint="left_hip_pitch_joint"/>
    <jointpos name="left_knee_pos"     joint="left_knee_joint"/>
    <jointpos name="left_ankle_pos"   joint="left_ankle_joint"/>
    <jointpos name="right_hip_yaw_pos"     joint="right_hip_yaw_joint"/>
    <jointpos name="right_hip_roll_pos"   joint="right_hip_roll_joint"/>
    <jointpos name="right_hip_pitch_pos"    joint="right_hip_pitch_joint" />
    <jointpos name="right_knee_pos"     joint="right_knee_joint"/>
    <jointpos name="right_ankle_pos"   joint="right_ankle_joint"/>
    <jointpos name="torso_pos"    joint="torso_joint"/>
    <jointpos name="left_shoulder_pitch_pos"    joint="left_shoulder_pitch_joint"/>
    <jointpos name="left_shoulder_roll_pos"   joint="left_shoulder_roll_joint"/>
    <jointpos name="left_shoulder_yaw_pos"    joint="left_shoulder_yaw_joint" />
    <jointpos name="left_elbow_pos"     joint="left_elbow_joint"/>
    <jointpos name="right_shoulder_pitch_pos"   joint="right_shoulder_pitch_joint"/>
    <jointpos name="right_shoulder_roll_pos"    joint="right_shoulder_roll_joint"/>
    <jointpos name="right_shoulder_yaw_pos"    joint="right_shoulder_yaw_joint"/>
    <jointpos name="right_elbow_pos"    joint="right_elbow_joint"/>

    <jointvel name="left_hip_yaw_vel"     joint="left_hip_yaw_joint"/>
    <jointvel name="left_hip_roll_vel"   joint="left_hip_roll_joint"/>
    <jointvel name="left_hip_pitch_vel"    joint="left_hip_pitch_joint"/>
    <jointvel name="left_knee_vel"     joint="left_knee_joint"/>
    <jointvel name="left_ankle_vel"   joint="left_ankle_joint"/>
    <jointvel name="right_hip_yaw_vel"     joint="right_hip_yaw_joint"/>
    <jointvel name="right_hip_roll_vel"   joint="right_hip_roll_joint"/>
    <jointvel name="right_hip_pitch_vel"    joint="right_hip_pitch_joint" />
    <jointvel name="right_knee_vel"     joint="right_knee_joint"/>
    <jointvel name="right_ankle_vel"   joint="right_ankle_joint"/>
    <jointvel name="torso_vel"    joint="torso_joint"/>
    <jointvel name="left_shoulder_pitch_vel"    joint="left_shoulder_pitch_joint"/>
    <jointvel name="left_shoulder_roll_vel"   joint="left_shoulder_roll_joint"/>
    <jointvel name="left_shoulder_yaw_vel"    joint="left_shoulder_yaw_joint" />
    <jointvel name="left_elbow_vel"     joint="left_elbow_joint"/>
    <jointvel name="right_shoulder_pitch_vel"   joint="right_shoulder_pitch_joint"/>
    <jointvel name="right_shoulder_roll_vel"    joint="right_shoulder_roll_joint"/>
    <jointvel name="right_shoulder_yaw_vel"    joint="right_shoulder_yaw_joint"/>
    <jointvel name="right_elbow_vel"    joint="right_elbow_joint"/>

    <!-- <gyro name="imu-angular-velocity" site="imu" noise="5e-4" cutoff="34.9"/>
    <accelerometer name="imu-linear-acceleration" site="imu" noise="1e-2" cutoff="157"/> -->

    <accelerometer name="Body_Acc" site="imu" noise="1e-2" cutoff="157"/>

    <gyro name="Body_Gyro" site="imu" noise="5e-4" cutoff="34.9"/>

    <framepos name="Body_Pos" objtype=site objname="imu"/>

    <framequat name="Body_Quat" objtype=site objname="imu"/>
  </sensor>

  <!-- <keyframe>
    <key name="home"
      qpos="
    0 0 0.98
    1 0 0 0
    0 0 -0.4 0.8 -0.4
    0 0 -0.4 0.8 -0.4
    0
    0 0 0 0
    0 0 0 0"
    />
  </keyframe> -->
</mujoco>